<?xml version="1.0"?>
<robot 
  name="mycomb1">
  <link name="base_link">
      <inertial>
      <mass value="0.001"/>
      <origin rpy="0 0 0" xyz="0 0 0"/>
      <inertia ixx="0.000001" ixy="0" ixz="0" iyy="0.000001" iyz="0" izz="0.000001"/>
    </inertial>
  </link>

  <joint name="dummy_joint_copy" type="fixed">
      <origin xyz="0.5 0.0 0.0" rpy="0 0 0"/>
      <parent link="base_link"/>
      <child link="base_footprint_copy"/>
      <axis xyz="0 0 1"/>
  </joint>
  <link name="base_footprint_copy">
      <visual>
      <geometry>
          <mesh filename="package://robot_description/meshes/myagv/myagv_base.dae" scale="1 1 1"/>
      </geometry>
      <origin xyz="0.0 0.0 0.0" rpy="0.0 0.0 0.0"/>
      <material name="black">
          <color rgba="0.7 0.7 0.0 1.0"/>
      </material>
      </visual>   
  </link>
  <joint name="base_joint_copy" type="fixed">
      <origin xyz="0.0 0.0 0.0" rpy="0 0 0"/>
      <parent link="base_footprint_copy"/>
      <child link="base_up_copy"/>
      <axis xyz="0 0 1"/>
  </joint>
  <link name="base_up_copy">
      <visual>
      <geometry>
          <mesh filename="package://robot_description/meshes/myagv/myagv_up.dae" scale="1 1 1"/>
      </geometry>
      <origin xyz="0.0 0.0 0.0" rpy="0.0 0.0 0.0"/>
      <material name="black">
          <color rgba="0.7 0.7 0.0 1.0"/>
      </material>
      </visual>
  </link>
  <joint name="base_to_g_base_copy" type="fixed">
    <axis xyz="0 0 0"/>
    <limit effort = "1000.0" lower = "-3.14" upper = "3.14159" velocity = "0"/>
    <parent link="base_up_copy"/>
    <child link="g_base_copy"/>
    <origin xyz= "-0.1 0 0.13" rpy = "0 0 0"/>
  </joint>

    <link name="g_base_copy">
    <visual>
      <geometry>
        <mesh filename="package://robot_description/meshes/mycobot_280_pi/G_base.dae"/>
      </geometry>
      <origin xyz = "0.0 0 -0.03" rpy = "0 0 1.5708"/>
    </visual>
    <collision>
      <geometry>
        <mesh filename="package://robot_description/meshes/mycobot_280_pi/G_base.dae"/>
      </geometry>
      <origin xyz = "0.0 0 -0.03" rpy = "0 0 1.5708"/>
    </collision>
  </link>

  <link name="joint1_copy">
    <visual>
      <geometry>
	     <!--- 0.0 0 -0.04  1.5708 3.14159-->
       <mesh filename="package://robot_description/meshes/mycobot_280_pi/joint1_pi.dae"/>
      </geometry>
      <origin xyz = "0.0 0 0 " rpy = " 0 0 -1.5708"/>
    </visual>
    <collision>
      <geometry>
	     <!--- 0.0 0 -0.04  1.5708 3.14159-->
       <mesh filename="package://robot_description/meshes/mycobot_280_pi/joint1_pi.dae"/>
        </geometry>
        <origin xyz = "0.0 0 0 " rpy = " 0 0 -1.5708"/>
    </collision>
  </link>

  <link name="joint2_copy">
    <visual>
      <geometry>
       <mesh filename="package://robot_description/meshes/mycobot_280_pi/joint2.dae"/>
      </geometry>
      <origin xyz = "0.0 0 -0.06096 " rpy = " 0 0 -1.5708"/>
    </visual>
    <collision>
     <geometry>
       <mesh filename="package://robot_description/meshes/mycobot_280_pi/joint2.dae"/>
      </geometry>
      <origin xyz = "0.0 0 -0.06096 " rpy = " 0 0 -1.5708"/>
    </collision>
  </link>


  <link name="joint3_copy">
    <visual>
      <geometry>
       <mesh filename="package://robot_description/meshes/mycobot_280_pi/joint3.dae"/>
      </geometry>
    <origin xyz = "0.0 0 0.03256 " rpy = " 0 -1.5708 0"/>
    </visual>
    <collision>
      <geometry>
       <mesh filename="package://robot_description/meshes/mycobot_280_pi/joint3.dae"/>
      </geometry>
      <origin xyz = "0.0 0 0.03256 " rpy = " 0 -1.5708 0"/>
    </collision>
  </link>


  <link name="joint4_copy">
    <visual>
      <geometry>
       <!--- 0.0 0 -0.04 -->
       <mesh filename="package://robot_description/meshes/mycobot_280_pi/joint4.dae"/>
      </geometry>
      <origin xyz = "0.0 0 0.03056 " rpy = " 0 -1.5708 0"/>
    </visual>
    <collision>
      <geometry>
       <!--- 0.0 0 -0.04 -->
       <mesh filename="package://robot_description/meshes/mycobot_280_pi/joint4.dae"/>
      </geometry>
      <origin xyz = "0.0 0 0.03056 " rpy = " 0 -1.5708 0"/>
    </collision>
  </link>


  <link name="joint5_copy">
    <visual>
      <geometry>
       <!--- 0.0 0 -0.04 -->
       <mesh filename="package://robot_description/meshes/mycobot_280_pi/joint5.dae"/>
      </geometry>
    <origin xyz = "0.0 0 -0.03356 " rpy = " -1.5708 0 0"/>
    </visual>
    <collision>
       <geometry>
       <!--- 0.0 0 -0.04 -->
       <mesh filename="package://robot_description/meshes/mycobot_280_pi/joint5.dae"/>
      </geometry>
      <origin xyz = "0.0 0 -0.03356 " rpy = " -1.5708 0 0"/>
    </collision>
  </link>


  <link name="joint6_copy">
    <visual>
      <geometry>
       <!--- 0.0 0 -0.04 -->
       <mesh filename="package://robot_description/meshes/mycobot_280_pi/joint6.dae"/>
      </geometry>
    <origin xyz = "0 0.00 -0.038 " rpy = " 0 0 0"/>
    </visual>
    <collision>
      <geometry>
       <!--- 0.0 0 -0.04 -->
       <mesh filename="package://robot_description/meshes/mycobot_280_pi/joint6.dae"/>
      </geometry>
    <origin xyz = "0 0.00 -0.038 " rpy = " 0 0 0"/>
    </collision>
  </link>


  <link name="joint6_flange_copy">
    <visual>
      <geometry>
       <!--- 0.0 0 -0.04 -->
       <mesh filename="package://robot_description/meshes/mycobot_280_pi/joint7.dae"/>
      </geometry>
    <origin xyz = "0.0 0 -0.012 " rpy = " 0 0 0"/>
    </visual>
    <collision>
      <geometry>
       <!--- 0.0 0 -0.04 -->
       <mesh filename="package://robot_description/meshes/mycobot_280_pi/joint7.dae"/>
      </geometry>
    <origin xyz = "0.0 0 -0.012 " rpy = " 0 0 0"/>
    </collision>
  </link>

  <link name="gripper_base_copy">
    <visual>
      <geometry>
       <mesh filename="package://robot_description/meshes/mycobot_280_pi/gripper_base.dae"/>
      </geometry>
    <origin xyz = "0.0 0.0077 -0.012" rpy = " 0 0 0"/>
    </visual>
    <collision>
      <geometry>
       <mesh filename="package://robot_description/meshes/mycobot_280_pi/gripper_base.dae"/>
      </geometry>
    <origin xyz = "0.0 0.0077 -0.012 " rpy = " 0 0 0"/>
    </collision>
  </link>

  <link name="gripper_left1_copy">
    <visual>
      <geometry>
       <!--- 0.0 0 -0.04 -->
       <mesh filename="package://robot_description/meshes/mycobot_280_pi/gripper_left1.dae"/>
      </geometry>
    <origin xyz = "0.039 -0.0133 -0.012 " rpy = " 0 0 0"/>
    <!-- <origin xyz = "0.0 0 -0.012 " rpy = " 0 0 0"/> -->
    </visual>
    <collision>
      <geometry>
       <mesh filename="package://robot_description/meshes/mycobot_280_pi/gripper_left1.dae"/>
      </geometry>
        <origin xyz = "-0.039 -0.0133 -0.012 " rpy = " 0 0 0"/>
    </collision>
  </link>

  <link name="gripper_left2_copy">
    <visual>
      <geometry>
       <mesh filename="package://robot_description/meshes/mycobot_280_pi/gripper_left2.dae"/>
      </geometry>
    <origin xyz = "0.005 -0.0195 -0.012 " rpy = " 0 0 0"/>
    </visual>
    <collision>
      <geometry>
       <mesh filename="package://robot_description/meshes/mycobot_280_pi/gripper_left2.dae"/>
      </geometry>
        <origin xyz = "-0.005 -0.0195 -0.012 " rpy = " 0 0 0"/>
    </collision>
  </link>

  <link name="gripper_left3_copy">
    <visual>
      <geometry>
       <mesh filename="package://robot_description/meshes/mycobot_280_pi/gripper_left3.dae"/>
      </geometry>
    <origin xyz = "0.012 0.0025 -0.012 " rpy = " 0 0 0"/>
    <!-- <origin xyz = "0.0 0 0 " rpy = " 0 0 0"/> -->

    </visual>
    <collision>
      <geometry>
       <mesh filename="package://robot_description/meshes/mycobot_280_pi/gripper_left3.dae"/>
      </geometry>
    <origin xyz = "0.012 0.0025 -0.012" rpy = " 0 0 0"/>
    </collision>
  </link>

  <link name="gripper_right1_copy">
    <visual>
      <geometry>
       <mesh filename="package://robot_description/meshes/mycobot_280_pi/gripper_right1.dae"/>
      </geometry>
    <origin xyz = "-0.039 -0.0133 -0.012 " rpy = " 0 0 0"/>
    </visual>
    <collision>
      <geometry>
       <mesh filename="package://robot_description/meshes/mycobot_280_pi/gripper_right1.dae"/>
      </geometry>
        <origin xyz = "-0.039 -0.0133 -0.012 " rpy = " 0 0 0"/>
    </collision>
  </link>

  <link name="gripper_right2_copy">
    <visual>
      <geometry>
       <mesh filename="package://robot_description/meshes/mycobot_280_pi/gripper_right2.dae"/>
      </geometry>
    <origin xyz = "-0.005 -0.0195 -0.012 " rpy = " 0 0 0"/>
    </visual>
    <collision>
      <geometry>
       <mesh filename="package://robot_description/meshes/mycobot_280_pi/gripper_right2.dae"/>
      </geometry>
        <origin xyz = "-0.005 -0.0195 -0.012 " rpy = " 0 0 0"/>
    </collision>
  </link>

  <link name="gripper_right3_copy">
    <visual>
      <geometry>
       <mesh filename="package://robot_description/meshes/mycobot_280_pi/gripper_right3.dae"/>
      </geometry>
    <origin xyz = "-0.012 0.0025 -0.012 " rpy = " 0 0 0"/>
    </visual>
    <collision>
      <geometry>
       <mesh filename="package://robot_description/meshes/mycobot_280_pi/gripper_right3.dae"/>
      </geometry>
    <origin xyz = "-0.012 0.0025 -0.012" rpy = " 0 0 0"/>
    </collision>
  </link>

  <joint name="g_base_to_joint1_copy" type="fixed">
    <axis xyz="0 0 0"/>
    <limit effort = "1000.0" lower = "-6.2831853" upper = "6.2831853" velocity = "0"/>
    <parent link="g_base_copy"/>
    <child link="joint1_copy"/>
    <origin xyz= "0 0 0" rpy = "0 0 0"/>  
  </joint>

  <joint name="joint2_to_joint1_copy" type="revolute">
    <axis xyz="0 0 1"/>
    <limit effort = "1000.0" lower = "-6.2831853" upper = "6.2831853" velocity = "0"/>
    <parent link="joint1_copy"/>
    <child link="joint2_copy"/>
    <origin xyz= "0 0 0.13156" rpy = "0 0 0"/>  
  </joint>

  <joint name="joint3_to_joint2_copy" type="revolute">
    <axis xyz="0 0 1"/>
    <limit effort = "1000.0" lower = "-6.2831853" upper = "6.2831853" velocity = "0"/>
    <parent link="joint2_copy"/>
    <child link="joint3_copy"/>
    <origin xyz= "0 0  0" rpy = "0 1.5708 -1.5708"/>  
  </joint>

  <joint name="joint4_to_joint3_copy" type="revolute">
    <axis xyz=" 0 0 1"/>
    <limit effort = "1000.0" lower = "-6.2831853" upper = "6.2831853" velocity = "0"/>
    <parent link="joint3_copy"/>
    <child link="joint4_copy"/>
    <origin xyz= "  -0.1104 0 0   " rpy = "0 0 0"/>  
  </joint>

  <joint name="joint5_to_joint4_copy" type="revolute">
    <axis xyz=" 0 0 1"/>
    <limit effort = "1000.0" lower = "-6.2831853" upper = "6.2831853" velocity = "0"/>
    <parent link="joint4_copy"/>
    <child link="joint5_copy"/>
    <origin xyz= "-0.096 0 0.06462" rpy = "0 0 -1.5708"/>  
  </joint>

  <joint name="joint6_to_joint5_copy" type="revolute">
    <axis xyz="0 0 1"/>
    <limit effort = "1000.0" lower = "-6.2831853" upper = "6.2831853" velocity = "0"/>
    <parent link="joint5_copy"/>
    <child link="joint6_copy"/>
    <origin xyz= "0 -0.07318 0" rpy = "1.5708 -1.5708 0"/>  
  </joint>

  <joint name="joint6output_to_joint6_copy" type="revolute">
    <axis xyz="0 0 1"/>
    <limit effort = "1000.0" lower = "-6.2831853" upper = "6.2831853" velocity = "0"/>
    <parent link="joint6_copy"/>
    <child link="joint6_flange_copy"/>
    <origin xyz= "0 0.0456 0" rpy = "-1.5708 0 0"/>  
  </joint>

  <joint name="joint6output_to_gripper_base_copy" type="fixed">
    <!-- <axis xyz="0 0 1"/>
    <limit effort = "1000.0" lower = "-3.14" upper = "3.14159" velocity = "0"/> -->
    <parent link="joint6_flange_copy"/>
    <child link="gripper_base_copy"/>
    <origin xyz= "0 0 0.0268" rpy = "1.5708 0 3.14159"/>  
  </joint>

  <joint name="gripper_controller" type="revolute">
    <axis xyz="0 0 1"/>
    <limit effort = "1000.0" lower = "-0.7" upper = "0.15" velocity = "0"/>
    <parent link="gripper_base_copy"/>
    <child link="gripper_left3_copy"/>
    <origin xyz= "-0.012 0.005 0" rpy = "0 0 0"/> 
  </joint>

  <joint name="gripper_base_to_gripper_left2_copy" type="revolute">
    <axis xyz="0 0 1"/>
    <limit effort = "1000.0" lower = "-0.8" upper = "0.5" velocity = "0"/>
    <parent link="gripper_base_copy"/>
    <child link="gripper_left2_copy"/>
    <origin xyz= "-0.005 0.027 0" rpy = "0 0 0"/> 
    <mimic joint="gripper_controller" multiplier="1.0" offset="0" />
  </joint>

  <joint name="gripper_left3_to_gripper_left1_copy" type="revolute">
    <axis xyz="0 0 1"/>
    <limit effort = "1000.0" lower = "-0.5" upper = "0.5" velocity = "0"/>
    <parent link="gripper_left3_copy"/>
    <child link="gripper_left1_copy"/>
    <origin xyz= "-0.027 0.016 0" rpy = "0 0 0"/> 
    <mimic joint="gripper_controller" multiplier="-1.0" offset="0" />
  </joint>

  <joint name="gripper_base_to_gripper_right3_copy" type="revolute">
    <axis xyz="0 0 1"/>
    <limit effort = "1000.0" lower = "-0.15" upper = "0.7" velocity = "0"/>
    <parent link="gripper_base_copy"/>
    <child link="gripper_right3_copy"/>
    <origin xyz= "0.012 0.005 0" rpy = "0 0 0"/> 
    <mimic joint="gripper_controller" multiplier="-1.0" offset="0" />
  </joint>

  <joint name="gripper_base_to_gripper_right2_copy" type="revolute">
    <axis xyz="0 0 1"/>
    <limit effort = "1000.0" lower = "-0.5" upper = "0.8" velocity = "0"/>
    <parent link="gripper_base_copy"/>
    <child link="gripper_right2_copy"/>
    <origin xyz= "0.005 0.027 0" rpy = "0 0 0"/> 
    <mimic joint="gripper_controller" multiplier="-1.0" offset="0" />
  </joint>

  <joint name="gripper_right3_to_gripper_right1_copy" type="revolute">
    <axis xyz="0 0 1"/>
    <limit effort = "1000.0" lower = "-0.5" upper = "0.5" velocity = "0"/>
    <parent link="gripper_right3_copy"/>
    <child link="gripper_right1_copy"/>
    <origin xyz= "0.027 0.016 0" rpy = "0 0 0"/> 
    <mimic joint="gripper_controller" multiplier="1.0" offset="0" />
  </joint>

</robot>